<?xml version="1.0"?>
<robot name="ano_uav">

  <!-- Materials -->
  <material name="black">
    <color rgba="0.0 0.0 0.0 1.0"/>
  </material>
  <material name="red">
    <color rgba="1.0 0.0 0.0 1.0"/>
  </material>
  <material name="green">
    <color rgba="0.0 1.0 0.0 1.0"/>
  </material>
  <material name="blue">
    <color rgba="0.0 0.0 1.0 1.0"/>
  </material>

  <!-- Base link -->
  <link name="base_link">
    <visual>
      <origin xyz="0 0 0.0" rpy="0 0 0"/>
      <geometry>
        <cylinder length="0.12" radius="0.10"/>
      </geometry>
      <material name="blue"/>
    </visual>
    <collision>
      <origin xyz="0 0 0.0" rpy="0 0 0"/>
      <geometry>
        <cylinder length="0.12" radius="0.10"/>
      </geometry>
    </collision>
    <inertial>
      <mass value="1.5"/>
      <inertia ixx="0.0347" ixy="0" ixz="0" iyy="0.0347" iyz="0" izz="0.0675"/>
    </inertial>
  </link>

  <!-- Laser link -->
  <link name="laser_link">
    <visual>
      <origin xyz="0 0 0" rpy="0 0 0"/>
      <geometry>
        <cylinder length="0.02" radius="0.02"/>
      </geometry>
      <material name="black"/>
    </visual>
    <collision>
      <origin xyz="0 0 0" rpy="0 0 0"/>
      <geometry>
        <cylinder length="0.02" radius="0.02"/>
      </geometry>
    </collision>
    <inertial>
      <mass value="0.1"/>
      <inertia ixx="0.0001" ixy="0" ixz="0" iyy="0.0001" iyz="0" izz="0.0001"/>
    </inertial>
  </link>

  <!-- Laser joint -->
  <joint name="laser_joint" type="fixed">
    <parent link="base_link"/>
    <child link="laser_link"/>
    <origin xyz="0 0 0.075"/>
  </joint>

  <!-- IMU link -->
  <link name="imu_link">
    <visual>
      <origin xyz="0 0 0" rpy="0 0 0"/>
      <geometry>
        <sphere radius="0.05"/>
      </geometry>
      <material name="red"/>
    </visual>
    <collision>
      <origin xyz="0 0 0" rpy="0 0 0"/>
      <geometry>
        <sphere radius="0.05"/>
      </geometry>
    </collision>
    <inertial>
      <mass value="0.1"/>
      <inertia ixx="0.0001" ixy="0" ixz="0" iyy="0.0001" iyz="0" izz="0.0001"/>
    </inertial>
  </link>

  <!-- IMU joint -->
  <joint name="imu_joint" type="fixed">
    <parent link="base_link"/>
    <child link="imu_link"/>
    <origin xyz="0 0 0.1"/>
  </joint>

  <!-- Rotor links and joints -->
  <xacro:macro name="rotor" params="name x y">
    <link name="${name}_link">
      <visual>
        <origin xyz="0 0 0" rpy="0 0 0"/>
        <geometry>
          <cylinder length="0.01" radius="0.1"/>
        </geometry>
        <material name="green"/>
      </visual>
      <collision>
        <origin xyz="0 0 0" rpy="0 0 0"/>
        <geometry>
          <cylinder length="0.01" radius="0.1"/>
        </geometry>
      </collision>
      <inertial>
        <mass value="0.1"/>
        <inertia ixx="0.0001" ixy="0" ixz="0" iyy="0.0001" iyz="0" izz="0.0002"/>
      </inertial>
    </link>

    <joint name="${name}_joint" type="continuous">
      <parent link="base_link"/>
      <child link="${name}_link"/>
      <origin xyz="${x} ${y} 0.06"/>
      <axis xyz="0 0 1"/>
    </joint>
  </xacro:macro>

  <xacro:rotor name="rotor_front_right" x="0.1" y="-0.1"/>
  <xacro:rotor name="rotor_front_left" x="0.1" y="0.1"/>
  <xacro:rotor name="rotor_back_right" x="-0.1" y="-0.1"/>
  <xacro:rotor name="rotor_back_left" x="-0.1" y="0.1"/>

  <!-- Camera link -->
  <link name="camera_link">
    <visual>
      <origin xyz="0 0 0" rpy="0 0 0"/>
      <geometry>
        <box size="0.05 0.05 0.05"/>
      </geometry>
      <material name="black"/>
    </visual>
    <collision>
      <origin xyz="0 0 0" rpy="0 0 0"/>
      <geometry>
        <box size="0.05 0.05 0.05"/>
      </geometry>
    </collision>
    <inertial>
      <mass value="0.1"/>
      <inertia ixx="0.0001" ixy="0" ixz="0" iyy="0.0001" iyz="0" izz="0.0001"/>
    </inertial>
  </link>

  <!-- Camera joint -->
  <joint name="camera_joint" type="fixed">
    <parent link="base_link"/>
    <child link="camera_link"/>
    <origin xyz="0.1 0 -0.05" rpy="0 0.7854 0"/>
  </joint>

</robot>
